Workbook

Sheet Attendance Report
A1: HHC 192nd ENGINEER BATTALION | I1: STRENGTH SUMMARY
I2: HHC 192nd Engineer Battalion
A3: Attendance Report | I3: Category | J3: Total | K3: Present | L3: % Present
I4: Officers | J4: =COUNTIF(B10:B94,"2LT")+COUNTIF(B10:B94,"1LT")+COUNTIF(B10:B94,"CPT")+COUNTIF(B10:B94,"MAJ")+COUNTIF(B10:B94,"LTC")+COUNTIF(B10:B94,"COL")+COUNTIF(B10:B94,"CDT") -> 25 | K4: =COUNTIFS(B10:B94,"2LT",F10:F94,"Present")+COUNTIFS(B10:B94,"1LT",F10:F94,"Present")+COUNTIFS(B10:B94,"CPT",F10:F94,"Present")+COUNTIFS(B10:B94,"MAJ",F10:F94,"Present")+COUNTIFS(B10:B94,"LTC",F10:F94,"Present")+COUNTIFS(B10:B94,"COL",F10:F94,"Present")+COUNTIFS(B10:B94,"CDT",F10:F94,"Present") -> 18 | L4: =IF(J4=0,0,K4/J4) -> 0.72
A5: STATUS LEGEND | I5: Warrant Officers | J5: =COUNTIF(B10:B94,"WO1")+COUNTIF(B10:B94,"CW2")+COUNTIF(B10:B94,"CW3")+COUNTIF(B10:B94,"CW4")+COUNTIF(B10:B94,"CW5") -> 2 | K5: =COUNTIFS(B10:B94,"WO1",F10:F94,"Present")+COUNTIFS(B10:B94,"CW2",F10:F94,"Present")+COUNTIFS(B10:B94,"CW3",F10:F94,"Present")+COUNTIFS(B10:B94,"CW4",F10:F94,"Present")+COUNTIFS(B10:B94,"CW5",F10:F94,"Present") -> 1 | L5: =IF(J5=0,0,K5/J5) -> 0.5
B6: Present | I6: Enlisted (All) | J6: =COUNTA(B10:B94)-J4-J5 -> 58 | K6: =COUNTIF(F10:F94,"Present")-K4-K5 -> 46 | L6: =IF(J6=0,0,K6/J6) -> 0.79310345
B7: SUTA | I7: Enlisted (Non-AGR) | J7: =COUNTIFS(D10:D94,"Enlisted",E10:E94,"<>Yes") -> 51 | K7: =COUNTIFS(D10:D94,"Enlisted",E10:E94,"<>Yes",F10:F94,"Present") -> 39 | L7: =IF(J7=0,0,K7/J7) -> 0.76470588
B8: AWOL | I8: TOTAL | J8: =COUNTA(B10:B94) -> 85 | K8: =COUNTIF(F10:F94,"Present") -> 65 | L8: =IF(J8=0,0,K8/J8) -> 0.76470588
A9: Section | B9: Rank | C9: Name | D9: Category | E9: AGR | F9: Status | G9: Remarks | H9: Location
A10: CMD | B10: CSM | C10: RIOSSOTO ERNESTO | D10: Enlisted | F10: Present | H10: Stratford Armory
A11: CMD | B11: LTC | C11: MILLER CHRISTOPHER | D11: Officer | F11: Present | H11: Stratford Armory
A12: CMD | B12: MAJ | C12: GABER, AARON | D12: Officer | F12: Off-Site Training | G12: CST -> DRUM | H12: Stratford Armory
A13: CMD | B13: MAJ | C13: GIUNTO JUSTIN H | D13: Officer | F13: Present | H13: Stratford Armory
A14: CMD | B14: MAJ | C14: fleming | D14: Officer | F14: Present | H14: Stratford Armory
A15: HQ | B15: 1LT | C15: PRADO CARLOS ANDRES | D15: Officer | F15: Present | H15: Stratford Armory
A16: HQ | B16: 1SG | C16: MINICUCCI MARC | D16: Enlisted | F16: Present | H16: Stratford Armory
A17: S2 | B17: 2LT | C17: QUESNEL | D17: Officer | F17: Present | H17: Stratford Armory
A18: HQ | B18: CDT | C18: RUIZ NOAH RYAN | D18: Officer | F18: Other | G18: RSP | H18: Stratford Armory
A19: HQ | B19: PV1 | C19: CHARLESTON RICHIE SA | D19: Enlisted | F19: Other | G19: BCT | H19: Stratford Armory
A20: HQ | B20: SFC | C20: MARTOVICH RYAN | D20: Enlisted | E20: Yes | F20: Present | H20: Stratford Armory
A21: HQ | B21: SPC | C21: CARDENAS RIVALDO | D21: Enlisted | F21: Present | H21: Stratford Armory
A22: HQ | B22: SPC | C22: LANG AARON | D22: Enlisted | F22: Present | H22: Stratford Armory
A23: HQ | B23: SPC | C23: MEDINA JAELYNN | D23: Enlisted | F23: Present | H23: Stratford Armory
A24: HQ | B24: SPC | C24: STRENGOWSKI JENNA | D24: Enlisted | F24: Present | H24: Stratford Armory
A25: HQ | B25: SSG | C25: GONZALEZ DANIEL | D25: Enlisted | F25: Present | H25: Stratford Armory
A26: HQ | B26: SSG | C26: MIRANDA JOSUE | D26: Enlisted | E26: Yes | F26: Present | H26: Stratford Armory
A27: HQ | B27: SSG | C27: MONIZ RACHEL | D27: Enlisted | E27: Yes | F27: Present | H27: Stratford Armory
A28: HQ | B28: PFC | C28: ROPER JONATHAN | D28: Enlisted | F28: Present | H28: Stratford Armory
A29: HQ | B29: PV2 | C29: QUITVIZACA | D29: Enlisted | F29: Present | H29: Stratford Armory
A30: S1 | B30: PFC | C30: CRUZ ELIZABETH | D30: Enlisted | F30: Present | H30: Stratford Armory
A31: S1 | B31: PFC | C31: DECARLI DANIEL ALLEN | D31: Enlisted | F31: Present | H31: Stratford Armory
A32: S1 | B32: PFC | C32: MAYORGRANFABIAN LAIS | D32: Enlisted | F32: Present | H32: Stratford Armory
A33: S1 | B33: SFC | C33: ALBINO JESSICA | D33: Enlisted | E33: Yes | F33: Present | H33: Stratford Armory
A34: S1 | B34: SGT | C34: ADDAE CHRISTIAN | D34: Enlisted | F34: Present | H34: Stratford Armory
A35: S1 | B35: SGT | C35: BROWN DEYSHANAE KRI | D35: Enlisted | F35: SUTA | H35: Alt AT
A36: S1 | B36: SGT | C36: JARVIS STEPHANIE R | D36: Enlisted | F36: Present | H36: Stratford Armory
A37: S1 | B37: SGT | C37: PEREZ MONTERO ANDRE | D37: Enlisted | F37: Present | H37: Stratford Armory
A38: S1 | B38: SPC | C38: HUDSON ALDAINE | D38: Enlisted | F38: Present | H38: Stratford Armory
A39: S1 | B39: SSG | C39: SCHNEIDER CURTIS | D39: Enlisted | E39: Yes | F39: Present | H39: Stratford Armory
A40: S1 | B40: 2LT | C40: KALSON JAKE | D40: Officer | F40: Present | H40: Stratford Armory
...

Sheet HW
A1: HHC 192nd ENGINEER BATTALION
A3: H/W tracker
A5: STATUS LEGEND
B6: Present
B7: SUTA
B8: AWOL
A9: Section | B9: Rank | C9: Name | D9: Category | E9: Status | F9: Remarks | G9: H/W (JUN IDT) Pass / Fail
A10: CMD | B10: CSM | C10: RIOSSOTO ERNESTO | D10: Enlisted | E10: Present
A11: CMD | B11: LTC | C11: MILLER CHRISTOPHER | D11: Officer | E11: Present | G11: Did not take
A12: CMD | B12: MAJ | C12: GABER, AARON | D12: Officer | E12: Other | F12: ROTC SUPPORT
A13: CMD | B13: MAJ | C13: GIUNTO JUSTIN H | D13: Officer | E13: Present
A14: HQ | B14: 1LT | C14: PRADO CARLOS ANDRES | D14: Officer | E14: Present | G14: PASS
A15: HQ | B15: 1SG | C15: MINICUCCI MARC | D15: Enlisted | E15: Present | G15: PASS
A16: HQ | B16: 2LT | C16: HANG | D16: Officer
A17: S2 | B17: 2LT | C17: QUESNEL | D17: Officer | E17: Present | G17: PASS
A18: S3 | B18: 2LT | C18: WILLET | D18: Officer | E18: Present | G18: PASS
A19: HQ | B19: CDT | C19: RUIZ NOAH RYAN | D19: Officer | E19: Other | F19: ROTC
A20: HQ | B20: CPT | C20: HERRERA FREDDY | D20: Officer | E20: Present | G20: PASS
A21: HQ | B21: PV1 | C21: CHARLESTON RICHIE SA | D21: Enlisted | E21: Other | F21: BCT
A22: HQ | B22: SFC | C22: MARTOVICH RYAN | D22: Enlisted | E22: Present
A23: HQ | B23: SPC | C23: CARDENAS RIVALDO | D23: Enlisted | E23: Present | G23: PASS
A24: HQ | B24: SPC | C24: LANG AARON | D24: Enlisted | E24: Present | G24: PASS
A25: HQ | B25: SPC | C25: MEDINA JAELYNN | D25: Enlisted | E25: Present | G25: PASS
A26: HQ | B26: SPC | C26: STRENGOWSKI JENNA | D26: Enlisted | E26: Present | G26: PASS
A27: HQ | B27: SSG | C27: GONZALEZ DANIEL | D27: Enlisted | E27: Present | G27: PASS
A28: HQ | B28: SSG | C28: MIRANDA JOSUE | D28: Enlisted | E28: Present
A29: HQ | B29: SSG | C29: MONIZ RACHEL | D29: Enlisted | E29: Present
A30: HQ | B30: PFC | C30: ROPER JONATHAN | D30: Enlisted | E30: Present | G30: PASS
A31: S1 | B31: 1LT | C31: MAPU VICTORIA STEPHA | D31: Officer | E31: Other | F31: DEPLOYMENT
A32: S1 | B32: PFC | C32: CRUZ ELIZABETH | D32: Enlisted | E32: Present | G32: PASS
A33: S1 | B33: PFC | C33: DECARLI DANIEL ALLEN | D33: Enlisted | E33: SUTA
A34: S1 | B34: PFC | C34: MAYORGRANFABIAN LAIS | D34: Enlisted | E34: SUTA
A35: S1 | B35: SFC | C35: ALBINO JESSICA | D35: Enlisted | E35: Present | G35: PASS
A36: S1 | B36: SGT | C36: ADDAE CHRISTIAN | D36: Enlisted | E36: Present | G36: PASS
A37: S1 | B37: SGT | C37: BROWN DEYSHANAE KRI | D37: Enlisted | E37: Off-Site Training | F37: ALT AT
A38: S1 | B38: SGT | C38: JARVIS STEPHANIE R | D38: Enlisted | E38: Present | G38: PASS
A39: S1 | B39: SGT | C39: PEREZ MONTERO ANDRE | D39: Enlisted | E39: Present | G39: PASS
A40: S1 | B40: SPC | C40: HUDSON ALDAINE | D40: Enlisted | E40: Other | F40: PATERNITY LEAVE
A41: S1 | B41: SSG | C41: SCHNEIDER CURTIS | D41: Enlisted | E41: Present
A42: S1 | B42: 2LT | C42: KALSON JAKE | D42: Officer | E42: Present | G42: PASS
...

Sheet Due Outs
A1: Section | B1: NCOERS | C1: OER | D1: E5/E6 board preferences | E1: Sec Clearance | F1: eURI Survay
A2: HQ | B2: 46023 | C2: 0/1 | D2: 46085 | E2: 46055 | F2: 46032
A3: MED | B3: 0/0 | C3: 0/0 | D3: 46024 | E3: 0/2 | F3: 46148
A4: SURVEY | B4: 0/2 | C4: 0/0 | D4: 46084 | E4: 46023 | F4: 8/9 (1 not present)
A5: S1 | B5: 1/1 (w/ chap) | C5: 0 | D5: 46055 | E5: 46023 | F5: 46210
A6: S2 | B6: 0/0 | C6: 0/1 (blackwell) | D6: 46055 | F6: 46147
A7: S3 | B7: 0 | C7: 46056 | D7: 46055 | E7: 0/1 | F7: 13/14
A8: S4 | B8: 0/1 | C8: 0/1 (w/ rater) | D8: 0 | F8: 46242
A9: S6 | B9: 0/0 | C9: 0/0 | D9: 2/3 (1 with expired CAC) | E9: 46023 | F9: 46180
A10: Totals | B10: 46026 | C10: 46059 | D10: 13/15 | E10: 5/ | F10: 45/56

Sheet Location (Manual)
A1: HHC 192nd ENGINEER BATTALION — Location Tracker (Manual)
A3: Enter soldier counts per section per location. Totals auto-check against Attendance Report.
A5: INDICATOR LEGEND
B6: Totals match — all soldiers accounted for
B7: Mismatch — total does not equal Present count
B8: Partial — some sections not yet entered (blanks exist)
B10: Enter headcount per section →
A11: Location | B11: CMD | C11: HQ | D11: S1 | E11: S2 | F11: S3 | G11: S4 | H11: S6 | I11: MED | J11: SURVEY | K11: Row Total
A12: Stratford Armory | K12: =SUM(B12:J12) -> 0
A13: London Armory | K13: =SUM(B13:J13) -> 0
A14: Norwich Armory | K14: =SUM(B14:J14) -> 0
A15: Stone Ranch Military Reserve | K15: =SUM(B15:J15) -> 0
A16: Camp Nett | K16: =SUM(B16:J16) -> 0
A17: COLUMN TOTAL | B17: =SUM(B12:B16) -> 0 | C17: =SUM(C12:C16) -> 0 | D17: =SUM(D12:D16) -> 0 | E17: =SUM(E12:E16) -> 0 | F17: =SUM(F12:F16) -> 0 | G17: =SUM(G12:G16) -> 0 | H17: =SUM(H12:H16) -> 0 | I17: =SUM(I12:I16) -> 0 | ... K17: =SUM(K12:K16) -> 0
A19: HEADCOUNT CHECK
A20: Total Present (Attendance Report) | D20: =COUNTIF('Attendance Report'!F10:F97,"Present") -> 65
A21: Total Entered (All Locations) | D21: =K17 -> 0
A22: Difference | D22: =D20-D21 -> 65

Sheet Location Summary
A1: HHC 192nd ENGINEER BATTALION — Drill Location Tracker | N1: ATTENDANCE vs LOCATION CHECK
N2: Updates live from Attendance Report
A3: Location totals must match Present count — highlighted RED if mismatch | N3: Metric | O3: Count
N4: Total Assigned | O4: =COUNTA('Attendance Report'!B10:B98) -> 85
A5: INDICATOR LEGEND | N5: Total Present | O5: =COUNTIF('Attendance Report'!F10:F98,"Present") -> 65
B6: Totals match — all accounted for | N6: Assigned to a Location | O6: =B16 -> 84
B7: Mismatch — totals do not equal Present count | N7: Unassigned (no location) | O7: =COUNTIF('Attendance Report'!H10:H94,"") -> 0
N8: Difference (Present − Location Total) | O8: =O5-O6 -> -19
D9: Soldiers Present by Section at this Location
A10: Location | B10: Assigned to Location | C10: Present at Location | D10: CMD | E10: HQ | F10: S1 | G10: S2 | H10: S3 | I10: S4 | J10: S6 | K10: MED | L10: SURVEY
A11: Stratford Armory | B11: =COUNTIF('Attendance Report'!H10:H98,A11) -> 84 | C11: =COUNTIFS('Attendance Report'!H10:H98,A11,'Attendance Report'!F10:F98,"Present") -> 65 | D11: =COUNTIFS('Attendance Report'!H10:H98,A11,'Attendance Report'!A10:A98,"CMD") -> 5 | E11: =COUNTIFS('Attendance Report'!H10:H98,A11,'Attendance Report'!A10:A98,"HQ") -> 15 | F11: =COUNTIFS('Attendance Report'!H10:H98,A11,'Attendance Report'!A10:A98,"S1") -> 11 | G11: =COUNTIFS('Attendance Report'!H10:H98,A11,'Attendance Report'!A10:A98,"S2") -> 7 | H11: =COUNTIFS('Attendance Report'!H10:H98,A11,'Attendance Report'!A10:A98,"S3") -> 16 | I11: =COUNTIFS('Attendance Report'!H10:H98,A11,'Attendance Report'!A10:A98,"S4") -> 9 | J11: =COUNTIFS('Attendance Report'!H10:H98,A11,'Attendance Report'!A10:A98,"S6") -> 7 | K11: =COUNTIFS('Attendance Report'!H10:H98,A11,'Attendance Report'!A10:A98,"MED") -> 6 | L11: =COUNTIFS('Attendance Report'!H10:H98,A11,'Attendance Report'!A10:A98,"SURVEY") -> 8
A12: London Armory | B12: =COUNTIF('Attendance Report'!H10:H98,A12) -> 0 | C12: =COUNTIFS('Attendance Report'!H10:H98,A12,'Attendance Report'!F10:F98,"Present") -> 0 | D12: =COUNTIFS('Attendance Report'!H10:H98,A12,'Attendance Report'!A10:A98,"CMD") -> 0 | E12: =COUNTIFS('Attendance Report'!H10:H98,A12,'Attendance Report'!A10:A98,"HQ") -> 0 | F12: =COUNTIFS('Attendance Report'!H10:H98,A12,'Attendance Report'!A10:A98,"S1") -> 0 | G12: =COUNTIFS('Attendance Report'!H10:H98,A12,'Attendance Report'!A10:A98,"S2") -> 0 | H12: =COUNTIFS('Attendance Report'!H10:H98,A12,'Attendance Report'!A10:A98,"S3") -> 0 | I12: =COUNTIFS('Attendance Report'!H10:H98,A12,'Attendance Report'!A10:A98,"S4") -> 0 | J12: =COUNTIFS('Attendance Report'!H10:H98,A12,'Attendance Report'!A10:A98,"S6") -> 0 | K12: =COUNTIFS('Attendance Report'!H10:H98,A12,'Attendance Report'!A10:A98,"MED") -> 0 | L12: =COUNTIFS('Attendance Report'!H10:H98,A12,'Attendance Report'!A10:A98,"SURVEY") -> 0
A13: Norwich Armory | B13: =COUNTIF('Attendance Report'!H10:H98,A13) -> 0 | C13: =COUNTIFS('Attendance Report'!H10:H98,A13,'Attendance Report'!F10:F98,"Present") -> 0 | D13: =COUNTIFS('Attendance Report'!H10:H98,A13,'Attendance Report'!A10:A98,"CMD") -> 0 | E13: =COUNTIFS('Attendance Report'!H10:H98,A13,'Attendance Report'!A10:A98,"HQ") -> 0 | F13: =COUNTIFS('Attendance Report'!H10:H98,A13,'Attendance Report'!A10:A98,"S1") -> 0 | G13: =COUNTIFS('Attendance Report'!H10:H98,A13,'Attendance Report'!A10:A98,"S2") -> 0 | H13: =COUNTIFS('Attendance Report'!H10:H98,A13,'Attendance Report'!A10:A98,"S3") -> 0 | I13: =COUNTIFS('Attendance Report'!H10:H98,A13,'Attendance Report'!A10:A98,"S4") -> 0 | J13: =COUNTIFS('Attendance Report'!H10:H98,A13,'Attendance Report'!A10:A98,"S6") -> 0 | K13: =COUNTIFS('Attendance Report'!H10:H98,A13,'Attendance Report'!A10:A98,"MED") -> 0 | L13: =COUNTIFS('Attendance Report'!H10:H98,A13,'Attendance Report'!A10:A98,"SURVEY") -> 0
A14: Stone Ranch Military Reserve | B14: =COUNTIF('Attendance Report'!H10:H98,A14) -> 0 | C14: =COUNTIFS('Attendance Report'!H10:H98,A14,'Attendance Report'!F10:F98,"Present") -> 0 | D14: =COUNTIFS('Attendance Report'!H10:H98,A14,'Attendance Report'!A10:A98,"CMD") -> 0 | E14: =COUNTIFS('Attendance Report'!H10:H98,A14,'Attendance Report'!A10:A98,"HQ") -> 0 | F14: =COUNTIFS('Attendance Report'!H10:H98,A14,'Attendance Report'!A10:A98,"S1") -> 0 | G14: =COUNTIFS('Attendance Report'!H10:H98,A14,'Attendance Report'!A10:A98,"S2") -> 0 | H14: =COUNTIFS('Attendance Report'!H10:H98,A14,'Attendance Report'!A10:A98,"S3") -> 0 | I14: =COUNTIFS('Attendance Report'!H10:H98,A14,'Attendance Report'!A10:A98,"S4") -> 0 | J14: =COUNTIFS('Attendance Report'!H10:H98,A14,'Attendance Report'!A10:A98,"S6") -> 0 | K14: =COUNTIFS('Attendance Report'!H10:H98,A14,'Attendance Report'!A10:A98,"MED") -> 0 | L14: =COUNTIFS('Attendance Report'!H10:H98,A14,'Attendance Report'!A10:A98,"SURVEY") -> 0
A15: Camp Nett | B15: =COUNTIF('Attendance Report'!H10:H98,A15) -> 0 | C15: =COUNTIFS('Attendance Report'!H10:H98,A15,'Attendance Report'!F10:F98,"Present") -> 0 | D15: =COUNTIFS('Attendance Report'!H10:H98,A15,'Attendance Report'!A10:A98,"CMD") -> 0 | E15: =COUNTIFS('Attendance Report'!H10:H98,A15,'Attendance Report'!A10:A98,"HQ") -> 0 | F15: =COUNTIFS('Attendance Report'!H10:H98,A15,'Attendance Report'!A10:A98,"S1") -> 0 | G15: =COUNTIFS('Attendance Report'!H10:H98,A15,'Attendance Report'!A10:A98,"S2") -> 0 | H15: =COUNTIFS('Attendance Report'!H10:H98,A15,'Attendance Report'!A10:A98,"S3") -> 0 | I15: =COUNTIFS('Attendance Report'!H10:H98,A15,'Attendance Report'!A10:A98,"S4") -> 0 | J15: =COUNTIFS('Attendance Report'!H10:H98,A15,'Attendance Report'!A10:A98,"S6") -> 0 | K15: =COUNTIFS('Attendance Report'!H10:H98,A15,'Attendance Report'!A10:A98,"MED") -> 0 | L15: =COUNTIFS('Attendance Report'!H10:H98,A15,'Attendance Report'!A10:A98,"SURVEY") -> 0
A16: TOTAL | B16: =SUM(B11:B15) -> 84 | C16: =SUM(C11:C15) -> 65 | D16: =SUM(D11:D15) -> 5 | E16: =SUM(E11:E15) -> 15 | F16: =SUM(F11:F15) -> 11 | G16: =SUM(G11:G15) -> 7 | H16: =SUM(H11:H15) -> 16 | I16: =SUM(I11:I15) -> 9 | ... L16: =SUM(L11:L15) -> 8

Sheet Security Clearance
A1: HHC 192nd ENGINEER BATTALION | I1: CLEARANCE SUMMARY
I2: Auto-calculated from due dates
A3: Security Clearance — Form Update Tracker | I3: Category | J3: Count | K3: Active
I4: Overdue | J4: =COUNTIFS(D10:D28,"<"&TODAY(),F10:F28,"<>Yes") -> 8 | K4: =COUNTIFS(D10:D28,"<"&TODAY(),F10:F28,"<>Yes") -> 8
A5: STATUS LEGEND | I5: Due ≤ 90 Days | J5: =COUNTIFS(D10:D28,">="&TODAY(),D10:D28,"<="&(TODAY()+90),F10:F28,"<>Yes") -> 1 | K5: =COUNTIFS(D10:D28,">="&TODAY(),D10:D28,"<="&(TODAY()+90),F10:F28,"<>Yes") -> 1
B6: Overdue | I6: Current | J6: =COUNTIFS(D10:D28,">"&(TODAY()+90),F10:F28,"<>Yes") -> 0 | K6: =COUNTIFS(D10:D28,">"&(TODAY()+90),F10:F28,"<>Yes") -> 0
B7: Due within 90 days | I7: Complete | J7: =COUNTIF(F10:F28,"Yes") -> 10 | K7: N/A
B8: Complete | I8: TOTAL | J8: =COUNTA(A10:A28) -> 19 | K8: =J8-J7 -> 9
A9: Name | B9: Rank | C9: Eligibility | D9: Form Update Due | E9: Days Until Due | F9: Complete | G9: Remarks
A10: PARREIRA DANIEL JORGE | B10: SFC | C10: Secret | D10: 45666 | E10: =D10-TODAY() -> -603 | G10: Legal Paerwork Pending
A11: VASQUEZ FRANKLIN ALBERT | B11: SGT | C11: Secret | D11: 45683 | E11: =D11-TODAY() -> -586 | F11: Yes
A12: EIKLEBERRY ADAM JOHN | B12: SGT | C12: Secret | D12: 45690 | E12: =D12-TODAY() -> -579 | F12: Yes
A13: MEDINA JAELYNN SIERRA | B13: SPC | C13: Secret | D13: 45690 | E13: =D13-TODAY() -> -579 | F13: Yes
A14: JEANBAPTISTE TAMIKA ANDREE | B14: SPC | C14: Secret | D14: 45691 | E14: =D14-TODAY() -> -578 | G14: working on it
A15: PEREZ MONTERO ANDREA CARLA | B15: SGT | C15: Secret | D15: 45698 | E15: =D15-TODAY() -> -571 | F15: Yes
A16: PRADO CARLOS ANDRES | B16: 1LT | C16: Secret | D16: 45698 | E16: =D16-TODAY() -> -571 | F16: Yes
A17: BROWN MICHAEL DAVID | B17: CPL | C17: Secret | D17: 45910 | E17: =D17-TODAY() -> -359 | G17: last drill
A18: SUAZO ELVIS RAUL | B18: CPT | C18: SCI-ICD704 | D18: 46089 | E18: =D18-TODAY() -> -180 | F18: No
A19: DONLON MATTHEW THOMAS | B19: CPT | C19: Secret | D19: 46096 | E19: =D19-TODAY() -> -173
A20: CASO NATHAN MARTIN | B20: MAJ | C20: Secret | D20: 46103 | E20: =D20-TODAY() -> -166 | F20: Yes
A21: JOSEPH ALLEN | B21: SPC | C21: Secret | D21: 46103 | E21: =D21-TODAY() -> -166
A22: DWOMOHBARIMAH CHRISTIAN TABI | B22: SGT | C22: Secret | D22: 46111 | E22: =D22-TODAY() -> -158 | F22: Yes
A23: MARTOVICH RYAN STEPHEN | B23: SFC | C23: Secret | D23: 46130 | E23: =D23-TODAY() -> -139 | F23: Yes
A24: HORNUNG ASHLEY MAE JEANE | B24: SGT | C24: Secret | D24: 46240 | E24: =D24-TODAY() -> -29 | G24: WIP
A25: PETTWAY JAYKWAN | B25: CPL | C25: Secret | D25: 46240 | E25: =D25-TODAY() -> -29 | F25: Yes
A26: OBRIEN BRENNAN MICHAEL | B26: SPC | C26: Secret | D26: 46260 | E26: =D26-TODAY() -> -9
A27: BREHMER JOHN HENRY PAUL | B27: SGT | C27: Secret | D27: 46278 | E27: =D27-TODAY() -> 9 | F27: Yes
A28: BRAVO NAYELLI SHIRLEY | B28: SPC | C28: Secret | D28: 46298 | E28: =D28-TODAY() -> 29 | G28: WIP
A29: Venegas | F29: Yes
